<?xml version="1.0" encoding="UTF-8"?>
<testng-results ignored="0" total="8" passed="0" failed="4" skipped="4">
  <reporter-output>
  </reporter-output>
  <suite started-at="2021-09-10T12:55:14 CEST" name="NegativeLoginTestSuite" finished-at="2021-09-10T12:55:27 CEST" duration-ms="13444">
    <groups>
    </groups>
    <test started-at="2021-09-10T12:55:14 CEST" name="UserRegistrationTest1-CH" finished-at="2021-09-10T12:55:23 CEST" duration-ms="9567">
      <class name="local.HLVTestApp.loginandsignuptests.NegativeSignUpTests">
        <test-method is-config="true" signature="setUp(java.lang.String,org.testng.ITestContext)[pri:0, instance:local.HLVTestApp.loginandsignuptests.NegativeSignUpTests@7193666c]" started-at="2021-09-10T12:55:14 CEST" name="setUp" finished-at="2021-09-10T12:55:18 CEST" duration-ms="4104" status="PASS">
          <params>
            <param index="0">
              <value>
                <![CDATA[chrome]]>
              </value>
            </param>
            <param index="1">
              <value>
                <![CDATA[org.testng.TestRunner@54d9d12d]]>
              </value>
            </param>
          </params>
          <reporter-output>
          </reporter-output>
        </test-method> <!-- setUp -->
        <test-method signature="verifySuccessfullSignUpAction(java.lang.String,java.lang.String,java.lang.String,java.lang.String,java.lang.String,java.lang.String,java.lang.String,java.lang.String)[pri:0, instance:local.HLVTestApp.loginandsignuptests.NegativeSignUpTests@7193666c]" started-at="2021-09-10T12:55:18 CEST" name="verifySuccessfullSignUpAction" finished-at="2021-09-10T12:55:22 CEST" duration-ms="4151" status="FAIL">
          <params>
            <param index="0">
              <value>
                <![CDATA[testFirstName1]]>
              </value>
            </param>
            <param index="1">
              <value>
                <![CDATA[testLastName1]]>
              </value>
            </param>
            <param index="2">
              <value>
                <![CDATA[testUsername1]]>
              </value>
            </param>
            <param index="3">
              <value>
                <![CDATA[test1@hlv.com]]>
              </value>
            </param>
            <param index="4">
              <value>
                <![CDATA[testPassword1]]>
              </value>
            </param>
            <param index="5">
              <value>
                <![CDATA[testMobile1]]>
              </value>
            </param>
            <param index="6">
              <value>
                <![CDATA[User has been successfully registered.]]>
              </value>
            </param>
            <param index="7">
              <value>
                <![CDATA[Oops! There is already a user registered with the email provided.]]>
              </value>
            </param>
          </params>
          <exception class="java.lang.AssertionError">
            <message>
              <![CDATA[expected [Oops! There is already a user registered with the email provided.] but found [User has been successfully registered.]]]>
            </message>
            <full-stacktrace>
              <![CDATA[java.lang.AssertionError: expected [Oops! There is already a user registered with the email provided.] but found [User has been successfully registered.]
at org.testng.Assert.fail(Assert.java:99)
at org.testng.Assert.failNotEquals(Assert.java:1037)
at org.testng.Assert.assertEqualsImpl(Assert.java:140)
at org.testng.Assert.assertEquals(Assert.java:122)
at org.testng.Assert.assertEquals(Assert.java:629)
at org.testng.Assert.assertEquals(Assert.java:639)
at local.HLVTestApp.loginandsignuptests.PositiveSignUpTests.verifySuccessfullSignUpAction(PositiveSignUpTests.java:35)
at java.base/jdk.internal.reflect.NativeMethodAccessorImpl.invoke0(Native Method)
at java.base/jdk.internal.reflect.NativeMethodAccessorImpl.invoke(NativeMethodAccessorImpl.java:64)
at java.base/jdk.internal.reflect.DelegatingMethodAccessorImpl.invoke(DelegatingMethodAccessorImpl.java:43)
at java.base/java.lang.reflect.Method.invoke(Method.java:564)
at org.testng.internal.MethodInvocationHelper.invokeMethod(MethodInvocationHelper.java:133)
at org.testng.internal.TestInvoker.invokeMethod(TestInvoker.java:598)
at org.testng.internal.TestInvoker.invokeTestMethod(TestInvoker.java:173)
at org.testng.internal.MethodRunner.runInSequence(MethodRunner.java:46)
at org.testng.internal.TestInvoker$MethodInvocationAgent.invoke(TestInvoker.java:824)
at org.testng.internal.TestInvoker.invokeTestMethods(TestInvoker.java:146)
at org.testng.internal.TestMethodWorker.invokeTestMethods(TestMethodWorker.java:146)
at org.testng.internal.TestMethodWorker.run(TestMethodWorker.java:128)
at java.base/java.util.ArrayList.forEach(ArrayList.java:1511)
at org.testng.TestRunner.privateRun(TestRunner.java:794)
at org.testng.TestRunner.run(TestRunner.java:596)
at org.testng.SuiteRunner.runTest(SuiteRunner.java:377)
at org.testng.SuiteRunner.access$000(SuiteRunner.java:28)
at org.testng.SuiteRunner$SuiteWorker.run(SuiteRunner.java:418)
at org.testng.internal.thread.ThreadUtil.lambda$execute$0(ThreadUtil.java:64)
at java.base/java.util.concurrent.FutureTask.run(FutureTask.java:264)
at java.base/java.util.concurrent.ThreadPoolExecutor.runWorker(ThreadPoolExecutor.java:1130)
at java.base/java.util.concurrent.ThreadPoolExecutor$Worker.run(ThreadPoolExecutor.java:630)
at java.base/java.lang.Thread.run(Thread.java:832)
]]>
            </full-stacktrace>
          </exception> <!-- java.lang.AssertionError -->
          <reporter-output>
          </reporter-output>
        </test-method> <!-- verifySuccessfullSignUpAction -->
        <test-method is-config="true" signature="tearDown()[pri:0, instance:local.HLVTestApp.loginandsignuptests.NegativeSignUpTests@7193666c]" started-at="2021-09-10T12:55:22 CEST" name="tearDown" finished-at="2021-09-10T12:55:23 CEST" duration-ms="1260" status="PASS">
          <reporter-output>
          </reporter-output>
        </test-method> <!-- tearDown -->
        <test-method signature="verifyUnsuccessfullSignUpAction(java.lang.String,java.lang.String,java.lang.String,java.lang.String,java.lang.String,java.lang.String,java.lang.String,java.lang.String)[pri:0, instance:local.HLVTestApp.loginandsignuptests.NegativeSignUpTests@7193666c]" started-at="2021-09-10T12:55:23 CEST" name="verifyUnsuccessfullSignUpAction" description="User already exist" finished-at="2021-09-10T12:55:23 CEST" depends-on-methods="local.HLVTestApp.loginandsignuptests.PositiveSignUpTests.verifySuccessfullSignUpAction" duration-ms="1" status="SKIP">
          <exception class="java.lang.Throwable">
            <message>
              <![CDATA[Method NegativeSignUpTests.verifyUnsuccessfullSignUpAction(java.lang.String,java.lang.String,java.lang.String,java.lang.String,java.lang.String,java.lang.String,java.lang.String,java.lang.String)[pri:0, instance:local.HLVTestApp.loginandsignuptests.NegativeSignUpTests@7193666c] depends on not successfully finished methods]]>
            </message>
            <full-stacktrace>
              <![CDATA[java.lang.Throwable: Method NegativeSignUpTests.verifyUnsuccessfullSignUpAction(java.lang.String,java.lang.String,java.lang.String,java.lang.String,java.lang.String,java.lang.String,java.lang.String,java.lang.String)[pri:0, instance:local.HLVTestApp.loginandsignuptests.NegativeSignUpTests@7193666c] depends on not successfully finished methods
at org.testng.internal.TestInvoker.invokeTestMethods(TestInvoker.java:102)
at org.testng.internal.TestMethodWorker.invokeTestMethods(TestMethodWorker.java:146)
at org.testng.internal.TestMethodWorker.run(TestMethodWorker.java:128)
at java.base/java.util.ArrayList.forEach(ArrayList.java:1511)
at org.testng.TestRunner.privateRun(TestRunner.java:794)
at org.testng.TestRunner.run(TestRunner.java:596)
at org.testng.SuiteRunner.runTest(SuiteRunner.java:377)
at org.testng.SuiteRunner.access$000(SuiteRunner.java:28)
at org.testng.SuiteRunner$SuiteWorker.run(SuiteRunner.java:418)
at org.testng.internal.thread.ThreadUtil.lambda$execute$0(ThreadUtil.java:64)
at java.base/java.util.concurrent.FutureTask.run(FutureTask.java:264)
at java.base/java.util.concurrent.ThreadPoolExecutor.runWorker(ThreadPoolExecutor.java:1130)
at java.base/java.util.concurrent.ThreadPoolExecutor$Worker.run(ThreadPoolExecutor.java:630)
at java.base/java.lang.Thread.run(Thread.java:832)
]]>
            </full-stacktrace>
          </exception> <!-- java.lang.Throwable -->
          <reporter-output>
          </reporter-output>
        </test-method> <!-- verifyUnsuccessfullSignUpAction -->
      </class> <!-- local.HLVTestApp.loginandsignuptests.NegativeSignUpTests -->
    </test> <!-- UserRegistrationTest1-CH -->
    <test started-at="2021-09-10T12:55:14 CEST" name="UserRegistrationTest2-CH" finished-at="2021-09-10T12:55:23 CEST" duration-ms="9439">
      <class name="local.HLVTestApp.loginandsignuptests.NegativeSignUpTests">
        <test-method is-config="true" signature="setUp(java.lang.String,org.testng.ITestContext)[pri:0, instance:local.HLVTestApp.loginandsignuptests.NegativeSignUpTests@4550bb58]" started-at="2021-09-10T12:55:14 CEST" name="setUp" finished-at="2021-09-10T12:55:18 CEST" duration-ms="4006" status="PASS">
          <params>
            <param index="0">
              <value>
                <![CDATA[chrome]]>
              </value>
            </param>
            <param index="1">
              <value>
                <![CDATA[org.testng.TestRunner@6a6cb05c]]>
              </value>
            </param>
          </params>
          <reporter-output>
          </reporter-output>
        </test-method> <!-- setUp -->
        <test-method signature="verifySuccessfullSignUpAction(java.lang.String,java.lang.String,java.lang.String,java.lang.String,java.lang.String,java.lang.String,java.lang.String,java.lang.String)[pri:0, instance:local.HLVTestApp.loginandsignuptests.NegativeSignUpTests@4550bb58]" started-at="2021-09-10T12:55:18 CEST" name="verifySuccessfullSignUpAction" finished-at="2021-09-10T12:55:21 CEST" duration-ms="3622" status="FAIL">
          <params>
            <param index="0">
              <value>
                <![CDATA[testFirstName2]]>
              </value>
            </param>
            <param index="1">
              <value>
                <![CDATA[testLastName2]]>
              </value>
            </param>
            <param index="2">
              <value>
                <![CDATA[testUsername2]]>
              </value>
            </param>
            <param index="3">
              <value>
                <![CDATA[test2@hlv.com]]>
              </value>
            </param>
            <param index="4">
              <value>
                <![CDATA[testPassword2]]>
              </value>
            </param>
            <param index="5">
              <value>
                <![CDATA[testMobile2]]>
              </value>
            </param>
            <param index="6">
              <value>
                <![CDATA[User has been successfully registered.]]>
              </value>
            </param>
            <param index="7">
              <value>
                <![CDATA[Oops! There is already a user registered with the email provided.]]>
              </value>
            </param>
          </params>
          <exception class="java.lang.AssertionError">
            <message>
              <![CDATA[expected [Oops! There is already a user registered with the email provided.] but found [User has been successfully registered.]]]>
            </message>
            <full-stacktrace>
              <![CDATA[java.lang.AssertionError: expected [Oops! There is already a user registered with the email provided.] but found [User has been successfully registered.]
at org.testng.Assert.fail(Assert.java:99)
at org.testng.Assert.failNotEquals(Assert.java:1037)
at org.testng.Assert.assertEqualsImpl(Assert.java:140)
at org.testng.Assert.assertEquals(Assert.java:122)
at org.testng.Assert.assertEquals(Assert.java:629)
at org.testng.Assert.assertEquals(Assert.java:639)
at local.HLVTestApp.loginandsignuptests.PositiveSignUpTests.verifySuccessfullSignUpAction(PositiveSignUpTests.java:35)
at java.base/jdk.internal.reflect.NativeMethodAccessorImpl.invoke0(Native Method)
at java.base/jdk.internal.reflect.NativeMethodAccessorImpl.invoke(NativeMethodAccessorImpl.java:64)
at java.base/jdk.internal.reflect.DelegatingMethodAccessorImpl.invoke(DelegatingMethodAccessorImpl.java:43)
at java.base/java.lang.reflect.Method.invoke(Method.java:564)
at org.testng.internal.MethodInvocationHelper.invokeMethod(MethodInvocationHelper.java:133)
at org.testng.internal.TestInvoker.invokeMethod(TestInvoker.java:598)
at org.testng.internal.TestInvoker.invokeTestMethod(TestInvoker.java:173)
at org.testng.internal.MethodRunner.runInSequence(MethodRunner.java:46)
at org.testng.internal.TestInvoker$MethodInvocationAgent.invoke(TestInvoker.java:824)
at org.testng.internal.TestInvoker.invokeTestMethods(TestInvoker.java:146)
at org.testng.internal.TestMethodWorker.invokeTestMethods(TestMethodWorker.java:146)
at org.testng.internal.TestMethodWorker.run(TestMethodWorker.java:128)
at java.base/java.util.ArrayList.forEach(ArrayList.java:1511)
at org.testng.TestRunner.privateRun(TestRunner.java:794)
at org.testng.TestRunner.run(TestRunner.java:596)
at org.testng.SuiteRunner.runTest(SuiteRunner.java:377)
at org.testng.SuiteRunner.access$000(SuiteRunner.java:28)
at org.testng.SuiteRunner$SuiteWorker.run(SuiteRunner.java:418)
at org.testng.internal.thread.ThreadUtil.lambda$execute$0(ThreadUtil.java:64)
at java.base/java.util.concurrent.FutureTask.run(FutureTask.java:264)
at java.base/java.util.concurrent.ThreadPoolExecutor.runWorker(ThreadPoolExecutor.java:1130)
at java.base/java.util.concurrent.ThreadPoolExecutor$Worker.run(ThreadPoolExecutor.java:630)
at java.base/java.lang.Thread.run(Thread.java:832)
]]>
            </full-stacktrace>
          </exception> <!-- java.lang.AssertionError -->
          <reporter-output>
          </reporter-output>
        </test-method> <!-- verifySuccessfullSignUpAction -->
        <test-method is-config="true" signature="tearDown()[pri:0, instance:local.HLVTestApp.loginandsignuptests.NegativeSignUpTests@4550bb58]" started-at="2021-09-10T12:55:21 CEST" name="tearDown" finished-at="2021-09-10T12:55:23 CEST" duration-ms="1746" status="PASS">
          <reporter-output>
          </reporter-output>
        </test-method> <!-- tearDown -->
        <test-method signature="verifyUnsuccessfullSignUpAction(java.lang.String,java.lang.String,java.lang.String,java.lang.String,java.lang.String,java.lang.String,java.lang.String,java.lang.String)[pri:0, instance:local.HLVTestApp.loginandsignuptests.NegativeSignUpTests@4550bb58]" started-at="2021-09-10T12:55:23 CEST" name="verifyUnsuccessfullSignUpAction" description="User already exist" finished-at="2021-09-10T12:55:23 CEST" depends-on-methods="local.HLVTestApp.loginandsignuptests.PositiveSignUpTests.verifySuccessfullSignUpAction" duration-ms="0" status="SKIP">
          <exception class="java.lang.Throwable">
            <message>
              <![CDATA[Method NegativeSignUpTests.verifyUnsuccessfullSignUpAction(java.lang.String,java.lang.String,java.lang.String,java.lang.String,java.lang.String,java.lang.String,java.lang.String,java.lang.String)[pri:0, instance:local.HLVTestApp.loginandsignuptests.NegativeSignUpTests@4550bb58] depends on not successfully finished methods]]>
            </message>
            <full-stacktrace>
              <![CDATA[java.lang.Throwable: Method NegativeSignUpTests.verifyUnsuccessfullSignUpAction(java.lang.String,java.lang.String,java.lang.String,java.lang.String,java.lang.String,java.lang.String,java.lang.String,java.lang.String)[pri:0, instance:local.HLVTestApp.loginandsignuptests.NegativeSignUpTests@4550bb58] depends on not successfully finished methods
at org.testng.internal.TestInvoker.invokeTestMethods(TestInvoker.java:102)
at org.testng.internal.TestMethodWorker.invokeTestMethods(TestMethodWorker.java:146)
at org.testng.internal.TestMethodWorker.run(TestMethodWorker.java:128)
at java.base/java.util.ArrayList.forEach(ArrayList.java:1511)
at org.testng.TestRunner.privateRun(TestRunner.java:794)
at org.testng.TestRunner.run(TestRunner.java:596)
at org.testng.SuiteRunner.runTest(SuiteRunner.java:377)
at org.testng.SuiteRunner.access$000(SuiteRunner.java:28)
at org.testng.SuiteRunner$SuiteWorker.run(SuiteRunner.java:418)
at org.testng.internal.thread.ThreadUtil.lambda$execute$0(ThreadUtil.java:64)
at java.base/java.util.concurrent.FutureTask.run(FutureTask.java:264)
at java.base/java.util.concurrent.ThreadPoolExecutor.runWorker(ThreadPoolExecutor.java:1130)
at java.base/java.util.concurrent.ThreadPoolExecutor$Worker.run(ThreadPoolExecutor.java:630)
at java.base/java.lang.Thread.run(Thread.java:832)
]]>
            </full-stacktrace>
          </exception> <!-- java.lang.Throwable -->
          <reporter-output>
          </reporter-output>
        </test-method> <!-- verifyUnsuccessfullSignUpAction -->
      </class> <!-- local.HLVTestApp.loginandsignuptests.NegativeSignUpTests -->
    </test> <!-- UserRegistrationTest2-CH -->
    <test started-at="2021-09-10T12:55:14 CEST" name="UserRegistrationTest4-FF" finished-at="2021-09-10T12:55:27 CEST" duration-ms="13319">
      <class name="local.HLVTestApp.loginandsignuptests.NegativeSignUpTests">
        <test-method is-config="true" signature="setUp(java.lang.String,org.testng.ITestContext)[pri:0, instance:local.HLVTestApp.loginandsignuptests.NegativeSignUpTests@72967906]" started-at="2021-09-10T12:55:14 CEST" name="setUp" finished-at="2021-09-10T12:55:24 CEST" duration-ms="10206" status="PASS">
          <params>
            <param index="0">
              <value>
                <![CDATA[firefox]]>
              </value>
            </param>
            <param index="1">
              <value>
                <![CDATA[org.testng.TestRunner@40a4337a]]>
              </value>
            </param>
          </params>
          <reporter-output>
          </reporter-output>
        </test-method> <!-- setUp -->
        <test-method signature="verifySuccessfullSignUpAction(java.lang.String,java.lang.String,java.lang.String,java.lang.String,java.lang.String,java.lang.String,java.lang.String,java.lang.String)[pri:0, instance:local.HLVTestApp.loginandsignuptests.NegativeSignUpTests@72967906]" started-at="2021-09-10T12:55:24 CEST" name="verifySuccessfullSignUpAction" finished-at="2021-09-10T12:55:25 CEST" duration-ms="1523" status="FAIL">
          <params>
            <param index="0">
              <value>
                <![CDATA[testFirstName4]]>
              </value>
            </param>
            <param index="1">
              <value>
                <![CDATA[testLastName4]]>
              </value>
            </param>
            <param index="2">
              <value>
                <![CDATA[testUsername4]]>
              </value>
            </param>
            <param index="3">
              <value>
                <![CDATA[test4@hlv.com]]>
              </value>
            </param>
            <param index="4">
              <value>
                <![CDATA[testPassword4]]>
              </value>
            </param>
            <param index="5">
              <value>
                <![CDATA[testMobile4]]>
              </value>
            </param>
            <param index="6">
              <value>
                <![CDATA[User has been successfully registered.]]>
              </value>
            </param>
            <param index="7">
              <value>
                <![CDATA[Oops! There is already a user registered with the email provided.]]>
              </value>
            </param>
          </params>
          <exception class="java.lang.AssertionError">
            <message>
              <![CDATA[expected [Oops! There is already a user registered with the email provided.] but found [User has been successfully registered.]]]>
            </message>
            <full-stacktrace>
              <![CDATA[java.lang.AssertionError: expected [Oops! There is already a user registered with the email provided.] but found [User has been successfully registered.]
at org.testng.Assert.fail(Assert.java:99)
at org.testng.Assert.failNotEquals(Assert.java:1037)
at org.testng.Assert.assertEqualsImpl(Assert.java:140)
at org.testng.Assert.assertEquals(Assert.java:122)
at org.testng.Assert.assertEquals(Assert.java:629)
at org.testng.Assert.assertEquals(Assert.java:639)
at local.HLVTestApp.loginandsignuptests.PositiveSignUpTests.verifySuccessfullSignUpAction(PositiveSignUpTests.java:35)
at java.base/jdk.internal.reflect.NativeMethodAccessorImpl.invoke0(Native Method)
at java.base/jdk.internal.reflect.NativeMethodAccessorImpl.invoke(NativeMethodAccessorImpl.java:64)
at java.base/jdk.internal.reflect.DelegatingMethodAccessorImpl.invoke(DelegatingMethodAccessorImpl.java:43)
at java.base/java.lang.reflect.Method.invoke(Method.java:564)
at org.testng.internal.MethodInvocationHelper.invokeMethod(MethodInvocationHelper.java:133)
at org.testng.internal.TestInvoker.invokeMethod(TestInvoker.java:598)
at org.testng.internal.TestInvoker.invokeTestMethod(TestInvoker.java:173)
at org.testng.internal.MethodRunner.runInSequence(MethodRunner.java:46)
at org.testng.internal.TestInvoker$MethodInvocationAgent.invoke(TestInvoker.java:824)
at org.testng.internal.TestInvoker.invokeTestMethods(TestInvoker.java:146)
at org.testng.internal.TestMethodWorker.invokeTestMethods(TestMethodWorker.java:146)
at org.testng.internal.TestMethodWorker.run(TestMethodWorker.java:128)
at java.base/java.util.ArrayList.forEach(ArrayList.java:1511)
at org.testng.TestRunner.privateRun(TestRunner.java:794)
at org.testng.TestRunner.run(TestRunner.java:596)
at org.testng.SuiteRunner.runTest(SuiteRunner.java:377)
at org.testng.SuiteRunner.access$000(SuiteRunner.java:28)
at org.testng.SuiteRunner$SuiteWorker.run(SuiteRunner.java:418)
at org.testng.internal.thread.ThreadUtil.lambda$execute$0(ThreadUtil.java:64)
at java.base/java.util.concurrent.FutureTask.run(FutureTask.java:264)
at java.base/java.util.concurrent.ThreadPoolExecutor.runWorker(ThreadPoolExecutor.java:1130)
at java.base/java.util.concurrent.ThreadPoolExecutor$Worker.run(ThreadPoolExecutor.java:630)
at java.base/java.lang.Thread.run(Thread.java:832)
]]>
            </full-stacktrace>
          </exception> <!-- java.lang.AssertionError -->
          <reporter-output>
          </reporter-output>
        </test-method> <!-- verifySuccessfullSignUpAction -->
        <test-method is-config="true" signature="tearDown()[pri:0, instance:local.HLVTestApp.loginandsignuptests.NegativeSignUpTests@72967906]" started-at="2021-09-10T12:55:25 CEST" name="tearDown" finished-at="2021-09-10T12:55:27 CEST" duration-ms="1541" status="PASS">
          <reporter-output>
          </reporter-output>
        </test-method> <!-- tearDown -->
        <test-method signature="verifyUnsuccessfullSignUpAction(java.lang.String,java.lang.String,java.lang.String,java.lang.String,java.lang.String,java.lang.String,java.lang.String,java.lang.String)[pri:0, instance:local.HLVTestApp.loginandsignuptests.NegativeSignUpTests@72967906]" started-at="2021-09-10T12:55:27 CEST" name="verifyUnsuccessfullSignUpAction" description="User already exist" finished-at="2021-09-10T12:55:27 CEST" depends-on-methods="local.HLVTestApp.loginandsignuptests.PositiveSignUpTests.verifySuccessfullSignUpAction" duration-ms="0" status="SKIP">
          <exception class="java.lang.Throwable">
            <message>
              <![CDATA[Method NegativeSignUpTests.verifyUnsuccessfullSignUpAction(java.lang.String,java.lang.String,java.lang.String,java.lang.String,java.lang.String,java.lang.String,java.lang.String,java.lang.String)[pri:0, instance:local.HLVTestApp.loginandsignuptests.NegativeSignUpTests@72967906] depends on not successfully finished methods]]>
            </message>
            <full-stacktrace>
              <![CDATA[java.lang.Throwable: Method NegativeSignUpTests.verifyUnsuccessfullSignUpAction(java.lang.String,java.lang.String,java.lang.String,java.lang.String,java.lang.String,java.lang.String,java.lang.String,java.lang.String)[pri:0, instance:local.HLVTestApp.loginandsignuptests.NegativeSignUpTests@72967906] depends on not successfully finished methods
at org.testng.internal.TestInvoker.invokeTestMethods(TestInvoker.java:102)
at org.testng.internal.TestMethodWorker.invokeTestMethods(TestMethodWorker.java:146)
at org.testng.internal.TestMethodWorker.run(TestMethodWorker.java:128)
at java.base/java.util.ArrayList.forEach(ArrayList.java:1511)
at org.testng.TestRunner.privateRun(TestRunner.java:794)
at org.testng.TestRunner.run(TestRunner.java:596)
at org.testng.SuiteRunner.runTest(SuiteRunner.java:377)
at org.testng.SuiteRunner.access$000(SuiteRunner.java:28)
at org.testng.SuiteRunner$SuiteWorker.run(SuiteRunner.java:418)
at org.testng.internal.thread.ThreadUtil.lambda$execute$0(ThreadUtil.java:64)
at java.base/java.util.concurrent.FutureTask.run(FutureTask.java:264)
at java.base/java.util.concurrent.ThreadPoolExecutor.runWorker(ThreadPoolExecutor.java:1130)
at java.base/java.util.concurrent.ThreadPoolExecutor$Worker.run(ThreadPoolExecutor.java:630)
at java.base/java.lang.Thread.run(Thread.java:832)
]]>
            </full-stacktrace>
          </exception> <!-- java.lang.Throwable -->
          <reporter-output>
          </reporter-output>
        </test-method> <!-- verifyUnsuccessfullSignUpAction -->
      </class> <!-- local.HLVTestApp.loginandsignuptests.NegativeSignUpTests -->
    </test> <!-- UserRegistrationTest4-FF -->
    <test started-at="2021-09-10T12:55:14 CEST" name="UserRegistrationTest3-FF" finished-at="2021-09-10T12:55:27 CEST" duration-ms="13444">
      <class name="local.HLVTestApp.loginandsignuptests.NegativeSignUpTests">
        <test-method is-config="true" signature="setUp(java.lang.String,org.testng.ITestContext)[pri:0, instance:local.HLVTestApp.loginandsignuptests.NegativeSignUpTests@6069db50]" started-at="2021-09-10T12:55:14 CEST" name="setUp" finished-at="2021-09-10T12:55:24 CEST" duration-ms="10410" status="PASS">
          <params>
            <param index="0">
              <value>
                <![CDATA[firefox]]>
              </value>
            </param>
            <param index="1">
              <value>
                <![CDATA[org.testng.TestRunner@6025e1b6]]>
              </value>
            </param>
          </params>
          <reporter-output>
          </reporter-output>
        </test-method> <!-- setUp -->
        <test-method signature="verifySuccessfullSignUpAction(java.lang.String,java.lang.String,java.lang.String,java.lang.String,java.lang.String,java.lang.String,java.lang.String,java.lang.String)[pri:0, instance:local.HLVTestApp.loginandsignuptests.NegativeSignUpTests@6069db50]" started-at="2021-09-10T12:55:24 CEST" name="verifySuccessfullSignUpAction" finished-at="2021-09-10T12:55:26 CEST" duration-ms="1751" status="FAIL">
          <params>
            <param index="0">
              <value>
                <![CDATA[testFirstName3]]>
              </value>
            </param>
            <param index="1">
              <value>
                <![CDATA[testLastName3]]>
              </value>
            </param>
            <param index="2">
              <value>
                <![CDATA[testUsername3]]>
              </value>
            </param>
            <param index="3">
              <value>
                <![CDATA[test3@hlv.com]]>
              </value>
            </param>
            <param index="4">
              <value>
                <![CDATA[testPassword3]]>
              </value>
            </param>
            <param index="5">
              <value>
                <![CDATA[testMobile3]]>
              </value>
            </param>
            <param index="6">
              <value>
                <![CDATA[User has been successfully registered.]]>
              </value>
            </param>
            <param index="7">
              <value>
                <![CDATA[Oops! There is already a user registered with the email provided.]]>
              </value>
            </param>
          </params>
          <exception class="java.lang.AssertionError">
            <message>
              <![CDATA[expected [Oops! There is already a user registered with the email provided.] but found [User has been successfully registered.]]]>
            </message>
            <full-stacktrace>
              <![CDATA[java.lang.AssertionError: expected [Oops! There is already a user registered with the email provided.] but found [User has been successfully registered.]
at org.testng.Assert.fail(Assert.java:99)
at org.testng.Assert.failNotEquals(Assert.java:1037)
at org.testng.Assert.assertEqualsImpl(Assert.java:140)
at org.testng.Assert.assertEquals(Assert.java:122)
at org.testng.Assert.assertEquals(Assert.java:629)
at org.testng.Assert.assertEquals(Assert.java:639)
at local.HLVTestApp.loginandsignuptests.PositiveSignUpTests.verifySuccessfullSignUpAction(PositiveSignUpTests.java:35)
at java.base/jdk.internal.reflect.NativeMethodAccessorImpl.invoke0(Native Method)
at java.base/jdk.internal.reflect.NativeMethodAccessorImpl.invoke(NativeMethodAccessorImpl.java:64)
at java.base/jdk.internal.reflect.DelegatingMethodAccessorImpl.invoke(DelegatingMethodAccessorImpl.java:43)
at java.base/java.lang.reflect.Method.invoke(Method.java:564)
at org.testng.internal.MethodInvocationHelper.invokeMethod(MethodInvocationHelper.java:133)
at org.testng.internal.TestInvoker.invokeMethod(TestInvoker.java:598)
at org.testng.internal.TestInvoker.invokeTestMethod(TestInvoker.java:173)
at org.testng.internal.MethodRunner.runInSequence(MethodRunner.java:46)
at org.testng.internal.TestInvoker$MethodInvocationAgent.invoke(TestInvoker.java:824)
at org.testng.internal.TestInvoker.invokeTestMethods(TestInvoker.java:146)
at org.testng.internal.TestMethodWorker.invokeTestMethods(TestMethodWorker.java:146)
at org.testng.internal.TestMethodWorker.run(TestMethodWorker.java:128)
at java.base/java.util.ArrayList.forEach(ArrayList.java:1511)
at org.testng.TestRunner.privateRun(TestRunner.java:794)
at org.testng.TestRunner.run(TestRunner.java:596)
at org.testng.SuiteRunner.runTest(SuiteRunner.java:377)
at org.testng.SuiteRunner.access$000(SuiteRunner.java:28)
at org.testng.SuiteRunner$SuiteWorker.run(SuiteRunner.java:418)
at org.testng.internal.thread.ThreadUtil.lambda$execute$0(ThreadUtil.java:64)
at java.base/java.util.concurrent.FutureTask.run(FutureTask.java:264)
at java.base/java.util.concurrent.ThreadPoolExecutor.runWorker(ThreadPoolExecutor.java:1130)
at java.base/java.util.concurrent.ThreadPoolExecutor$Worker.run(ThreadPoolExecutor.java:630)
at java.base/java.lang.Thread.run(Thread.java:832)
]]>
            </full-stacktrace>
          </exception> <!-- java.lang.AssertionError -->
          <reporter-output>
          </reporter-output>
        </test-method> <!-- verifySuccessfullSignUpAction -->
        <test-method is-config="true" signature="tearDown()[pri:0, instance:local.HLVTestApp.loginandsignuptests.NegativeSignUpTests@6069db50]" started-at="2021-09-10T12:55:26 CEST" name="tearDown" finished-at="2021-09-10T12:55:27 CEST" duration-ms="1235" status="PASS">
          <reporter-output>
          </reporter-output>
        </test-method> <!-- tearDown -->
        <test-method signature="verifyUnsuccessfullSignUpAction(java.lang.String,java.lang.String,java.lang.String,java.lang.String,java.lang.String,java.lang.String,java.lang.String,java.lang.String)[pri:0, instance:local.HLVTestApp.loginandsignuptests.NegativeSignUpTests@6069db50]" started-at="2021-09-10T12:55:27 CEST" name="verifyUnsuccessfullSignUpAction" description="User already exist" finished-at="2021-09-10T12:55:27 CEST" depends-on-methods="local.HLVTestApp.loginandsignuptests.PositiveSignUpTests.verifySuccessfullSignUpAction" duration-ms="0" status="SKIP">
          <exception class="java.lang.Throwable">
            <message>
              <![CDATA[Method NegativeSignUpTests.verifyUnsuccessfullSignUpAction(java.lang.String,java.lang.String,java.lang.String,java.lang.String,java.lang.String,java.lang.String,java.lang.String,java.lang.String)[pri:0, instance:local.HLVTestApp.loginandsignuptests.NegativeSignUpTests@6069db50] depends on not successfully finished methods]]>
            </message>
            <full-stacktrace>
              <![CDATA[java.lang.Throwable: Method NegativeSignUpTests.verifyUnsuccessfullSignUpAction(java.lang.String,java.lang.String,java.lang.String,java.lang.String,java.lang.String,java.lang.String,java.lang.String,java.lang.String)[pri:0, instance:local.HLVTestApp.loginandsignuptests.NegativeSignUpTests@6069db50] depends on not successfully finished methods
at org.testng.internal.TestInvoker.invokeTestMethods(TestInvoker.java:102)
at org.testng.internal.TestMethodWorker.invokeTestMethods(TestMethodWorker.java:146)
at org.testng.internal.TestMethodWorker.run(TestMethodWorker.java:128)
at java.base/java.util.ArrayList.forEach(ArrayList.java:1511)
at org.testng.TestRunner.privateRun(TestRunner.java:794)
at org.testng.TestRunner.run(TestRunner.java:596)
at org.testng.SuiteRunner.runTest(SuiteRunner.java:377)
at org.testng.SuiteRunner.access$000(SuiteRunner.java:28)
at org.testng.SuiteRunner$SuiteWorker.run(SuiteRunner.java:418)
at org.testng.internal.thread.ThreadUtil.lambda$execute$0(ThreadUtil.java:64)
at java.base/java.util.concurrent.FutureTask.run(FutureTask.java:264)
at java.base/java.util.concurrent.ThreadPoolExecutor.runWorker(ThreadPoolExecutor.java:1130)
at java.base/java.util.concurrent.ThreadPoolExecutor$Worker.run(ThreadPoolExecutor.java:630)
at java.base/java.lang.Thread.run(Thread.java:832)
]]>
            </full-stacktrace>
          </exception> <!-- java.lang.Throwable -->
          <reporter-output>
          </reporter-output>
        </test-method> <!-- verifyUnsuccessfullSignUpAction -->
      </class> <!-- local.HLVTestApp.loginandsignuptests.NegativeSignUpTests -->
    </test> <!-- UserRegistrationTest3-FF -->
  </suite> <!-- NegativeLoginTestSuite -->
</testng-results>
