<?xml version="1.0" encoding="UTF-8"?>
<!-- Generated by org.testng.reporters.JUnitReportReporter -->
<testsuite hostname="SIXNS289" failures="3" tests="5" name="local.HLVTestApp.loginandsignuptests.NegativeLoginTests" time="23.754" errors="1" timestamp="2021-09-13T23:16:10 CEST" skipped="0">
  <testcase classname="local.HLVTestApp.loginandsignuptests.NegativeLoginTests" name="verifyUnsuccessfulLoginActionOnMainPage" time="2.475">
    <failure message="expected [http://localhost:8080/login] but found [http://localhost:8080/?username=incorrectUsername&amp;password=testPassword1]" type="java.lang.AssertionError">
      <![CDATA[java.lang.AssertionError: expected [http://localhost:8080/login] but found [http://localhost:8080/?username=incorrectUsername&password=testPassword1]
at org.testng.Assert.fail(Assert.java:99)
at org.testng.Assert.failNotEquals(Assert.java:1037)
at org.testng.Assert.assertEqualsImpl(Assert.java:140)
at org.testng.Assert.assertEquals(Assert.java:122)
at org.testng.Assert.assertEquals(Assert.java:629)
at org.testng.Assert.assertEquals(Assert.java:639)
at local.HLVTestApp.loginandsignuptests.NegativeLoginTests.verifyUnsuccessfulLoginActionOnMainPage(NegativeLoginTests.java:35)
at java.base/jdk.internal.reflect.NativeMethodAccessorImpl.invoke0(Native Method)
at java.base/jdk.internal.reflect.NativeMethodAccessorImpl.invoke(NativeMethodAccessorImpl.java:64)
at java.base/jdk.internal.reflect.DelegatingMethodAccessorImpl.invoke(DelegatingMethodAccessorImpl.java:43)
at java.base/java.lang.reflect.Method.invoke(Method.java:564)
at org.testng.internal.MethodInvocationHelper.invokeMethod(MethodInvocationHelper.java:133)
at org.testng.internal.TestInvoker.invokeMethod(TestInvoker.java:598)
at org.testng.internal.TestInvoker.invokeTestMethod(TestInvoker.java:173)
at org.testng.internal.MethodRunner.runInSequence(MethodRunner.java:46)
at org.testng.internal.TestInvoker$MethodInvocationAgent.invoke(TestInvoker.java:824)
at org.testng.internal.TestInvoker.invokeTestMethods(TestInvoker.java:146)
at org.testng.internal.TestMethodWorker.invokeTestMethods(TestMethodWorker.java:146)
at org.testng.internal.TestMethodWorker.run(TestMethodWorker.java:128)
at java.base/java.util.ArrayList.forEach(ArrayList.java:1511)
at org.testng.TestRunner.privateRun(TestRunner.java:794)
at org.testng.TestRunner.run(TestRunner.java:596)
at org.testng.SuiteRunner.runTest(SuiteRunner.java:377)
at org.testng.SuiteRunner.access$000(SuiteRunner.java:28)
at org.testng.SuiteRunner$SuiteWorker.run(SuiteRunner.java:418)
at org.testng.internal.thread.ThreadUtil.lambda$execute$0(ThreadUtil.java:64)
at java.base/java.util.concurrent.FutureTask.run(FutureTask.java:264)
at java.base/java.util.concurrent.ThreadPoolExecutor.runWorker(ThreadPoolExecutor.java:1130)
at java.base/java.util.concurrent.ThreadPoolExecutor$Worker.run(ThreadPoolExecutor.java:630)
at java.base/java.lang.Thread.run(Thread.java:832)
]]>
    </failure>
  </testcase> <!-- verifyUnsuccessfulLoginActionOnMainPage -->
  <system-out/>
  <testcase classname="local.HLVTestApp.loginandsignuptests.NegativeLoginTests" name="verifyUnsuccessfulLoginActionOnMainPage" time="3.083">
    <failure message="expected [http://localhost:8080/login] but found [http://localhost:8080/?username=incorrectUsername&amp;password=incorrectPassword]" type="java.lang.AssertionError">
      <![CDATA[java.lang.AssertionError: expected [http://localhost:8080/login] but found [http://localhost:8080/?username=incorrectUsername&password=incorrectPassword]
at org.testng.Assert.fail(Assert.java:99)
at org.testng.Assert.failNotEquals(Assert.java:1037)
at org.testng.Assert.assertEqualsImpl(Assert.java:140)
at org.testng.Assert.assertEquals(Assert.java:122)
at org.testng.Assert.assertEquals(Assert.java:629)
at org.testng.Assert.assertEquals(Assert.java:639)
at local.HLVTestApp.loginandsignuptests.NegativeLoginTests.verifyUnsuccessfulLoginActionOnMainPage(NegativeLoginTests.java:35)
at java.base/jdk.internal.reflect.NativeMethodAccessorImpl.invoke0(Native Method)
at java.base/jdk.internal.reflect.NativeMethodAccessorImpl.invoke(NativeMethodAccessorImpl.java:64)
at java.base/jdk.internal.reflect.DelegatingMethodAccessorImpl.invoke(DelegatingMethodAccessorImpl.java:43)
at java.base/java.lang.reflect.Method.invoke(Method.java:564)
at org.testng.internal.MethodInvocationHelper.invokeMethod(MethodInvocationHelper.java:133)
at org.testng.internal.TestInvoker.invokeMethod(TestInvoker.java:598)
at org.testng.internal.TestInvoker.invokeTestMethod(TestInvoker.java:173)
at org.testng.internal.MethodRunner.runInSequence(MethodRunner.java:46)
at org.testng.internal.TestInvoker$MethodInvocationAgent.invoke(TestInvoker.java:824)
at org.testng.internal.TestInvoker.invokeTestMethods(TestInvoker.java:146)
at org.testng.internal.TestMethodWorker.invokeTestMethods(TestMethodWorker.java:146)
at org.testng.internal.TestMethodWorker.run(TestMethodWorker.java:128)
at java.base/java.util.ArrayList.forEach(ArrayList.java:1511)
at org.testng.TestRunner.privateRun(TestRunner.java:794)
at org.testng.TestRunner.run(TestRunner.java:596)
at org.testng.SuiteRunner.runTest(SuiteRunner.java:377)
at org.testng.SuiteRunner.access$000(SuiteRunner.java:28)
at org.testng.SuiteRunner$SuiteWorker.run(SuiteRunner.java:418)
at org.testng.internal.thread.ThreadUtil.lambda$execute$0(ThreadUtil.java:64)
at java.base/java.util.concurrent.FutureTask.run(FutureTask.java:264)
at java.base/java.util.concurrent.ThreadPoolExecutor.runWorker(ThreadPoolExecutor.java:1130)
at java.base/java.util.concurrent.ThreadPoolExecutor$Worker.run(ThreadPoolExecutor.java:630)
at java.base/java.lang.Thread.run(Thread.java:832)
]]>
    </failure>
  </testcase> <!-- verifyUnsuccessfulLoginActionOnMainPage -->
  <system-out/>
  <testcase classname="local.HLVTestApp.loginandsignuptests.NegativeLoginTests" name="verifyUnsuccessfulLoginActionOnLoginPage" time="12.313">
    <error message="Error communicating with the remote browser. It may have died.
Build info: version: &#039;4.0.0-beta-4&#039;, revision: &#039;29f46d02dd&#039;
System info: host: &#039;SIXNS289&#039;, ip: &#039;192.168.0.14&#039;, os.name: &#039;Windows 10&#039;, os.arch: &#039;amd64&#039;, os.version: &#039;10.0&#039;, java.version: &#039;15&#039;
Driver info: org.openqa.selenium.chrome.ChromeDriver
Command: [8ba47be27fc1fc3f9cf9e57e041d5d77, screenshot {}]
Capabilities {acceptInsecureCerts: false, browserName: chrome, browserVersion: 93.0.4577.63, chrome: {chromedriverVersion: 93.0.4577.63 (ff5c0da2ec0ad..., userDataDir: C:\Users\ATATAL~1\AppData\L...}, goog:chromeOptions: {debuggerAddress: localhost:63761}, javascriptEnabled: true, networkConnectionEnabled: false, pageLoadStrategy: normal, platform: WINDOWS, platformName: WINDOWS, proxy: Proxy(), se:cdp: ws://localhost:63761/devtoo..., se:cdpVersion: 93.0.4577.63, setWindowRect: true, strictFileInteractability: false, timeouts: {implicit: 0, pageLoad: 300000, script: 30000}, unhandledPromptBehavior: dismiss and notify, webauthn:extension:credBlob: true, webauthn:extension:largeBlob: true, webauthn:virtualAuthenticators: true}" type="org.openqa.selenium.remote.UnreachableBrowserException">
      <![CDATA[org.openqa.selenium.remote.UnreachableBrowserException: Error communicating with the remote browser. It may have died.
Build info: version: '4.0.0-beta-4', revision: '29f46d02dd'
System info: host: 'SIXNS289', ip: '192.168.0.14', os.name: 'Windows 10', os.arch: 'amd64', os.version: '10.0', java.version: '15'
Driver info: org.openqa.selenium.chrome.ChromeDriver
Command: [8ba47be27fc1fc3f9cf9e57e041d5d77, screenshot {}]
Capabilities {acceptInsecureCerts: false, browserName: chrome, browserVersion: 93.0.4577.63, chrome: {chromedriverVersion: 93.0.4577.63 (ff5c0da2ec0ad..., userDataDir: C:\Users\ATATAL~1\AppData\L...}, goog:chromeOptions: {debuggerAddress: localhost:63761}, javascriptEnabled: true, networkConnectionEnabled: false, pageLoadStrategy: normal, platform: WINDOWS, platformName: WINDOWS, proxy: Proxy(), se:cdp: ws://localhost:63761/devtoo..., se:cdpVersion: 93.0.4577.63, setWindowRect: true, strictFileInteractability: false, timeouts: {implicit: 0, pageLoad: 300000, script: 30000}, unhandledPromptBehavior: dismiss and notify, webauthn:extension:credBlob: true, webauthn:extension:largeBlob: true, webauthn:virtualAuthenticators: true}
at org.openqa.selenium.remote.RemoteWebDriver.execute(RemoteWebDriver.java:636)
at org.openqa.selenium.remote.RemoteWebDriver.execute(RemoteWebDriver.java:667)
at org.openqa.selenium.remote.RemoteWebDriver.execute(RemoteWebDriver.java:671)
at org.openqa.selenium.remote.RemoteWebDriver.getScreenshotAs(RemoteWebDriver.java:347)
at local.HLVTestApp.base.TestUtilities.takeScreenshot(TestUtilities.java:29)
at local.HLVTestApp.listeners.TestListener.onTestFailure(TestListener.java:23)
at org.testng.internal.TestListenerHelper.runTestListeners(TestListenerHelper.java:96)
at org.testng.internal.TestInvoker.runTestResultListener(TestInvoker.java:219)
at org.testng.internal.TestInvoker.invokeMethod(TestInvoker.java:656)
at org.testng.internal.TestInvoker.invokeTestMethod(TestInvoker.java:173)
at org.testng.internal.MethodRunner.runInSequence(MethodRunner.java:46)
at org.testng.internal.TestInvoker$MethodInvocationAgent.invoke(TestInvoker.java:824)
at org.testng.internal.TestInvoker.invokeTestMethods(TestInvoker.java:146)
at org.testng.internal.TestMethodWorker.invokeTestMethods(TestMethodWorker.java:146)
at org.testng.internal.TestMethodWorker.run(TestMethodWorker.java:128)
at java.base/java.util.ArrayList.forEach(ArrayList.java:1511)
at org.testng.TestRunner.privateRun(TestRunner.java:794)
at org.testng.TestRunner.run(TestRunner.java:596)
at org.testng.SuiteRunner.runTest(SuiteRunner.java:377)
at org.testng.SuiteRunner.access$000(SuiteRunner.java:28)
at org.testng.SuiteRunner$SuiteWorker.run(SuiteRunner.java:418)
at org.testng.internal.thread.ThreadUtil.lambda$execute$0(ThreadUtil.java:64)
at java.base/java.util.concurrent.FutureTask.run(FutureTask.java:264)
at java.base/java.util.concurrent.ThreadPoolExecutor.runWorker(ThreadPoolExecutor.java:1130)
at java.base/java.util.concurrent.ThreadPoolExecutor$Worker.run(ThreadPoolExecutor.java:630)
at java.base/java.lang.Thread.run(Thread.java:832)
Caused by: java.io.UncheckedIOException: java.net.ConnectException: Connection refused: no further information: localhost/[0:0:0:0:0:0:0:1]:20347
at org.openqa.selenium.remote.http.netty.NettyHttpHandler.makeCall(NettyHttpHandler.java:79)
at org.openqa.selenium.remote.http.AddSeleniumUserAgent.lambda$apply$0(AddSeleniumUserAgent.java:42)
at org.openqa.selenium.remote.http.Filter.lambda$andFinally$1(Filter.java:56)
at org.openqa.selenium.remote.http.netty.NettyHttpHandler.execute(NettyHttpHandler.java:51)
at org.openqa.selenium.remote.http.AddSeleniumUserAgent.lambda$apply$0(AddSeleniumUserAgent.java:42)
at org.openqa.selenium.remote.http.Filter.lambda$andFinally$1(Filter.java:56)
at org.openqa.selenium.remote.http.netty.NettyClient.execute(NettyClient.java:105)
at org.openqa.selenium.remote.HttpCommandExecutor.execute(HttpCommandExecutor.java:181)
at org.openqa.selenium.remote.service.DriverCommandExecutor.invokeExecute(DriverCommandExecutor.java:162)
at org.openqa.selenium.remote.service.DriverCommandExecutor.execute(DriverCommandExecutor.java:137)
at org.openqa.selenium.remote.RemoteWebDriver.execute(RemoteWebDriver.java:612)
... 25 more
Caused by: java.net.ConnectException: Connection refused: no further information: localhost/[0:0:0:0:0:0:0:1]:20347
at org.asynchttpclient.netty.channel.NettyConnectListener.onFailure(NettyConnectListener.java:179)
at org.asynchttpclient.netty.channel.NettyChannelConnector$1.onFailure(NettyChannelConnector.java:108)
at org.asynchttpclient.netty.SimpleChannelFutureListener.operationComplete(SimpleChannelFutureListener.java:28)
at org.asynchttpclient.netty.SimpleChannelFutureListener.operationComplete(SimpleChannelFutureListener.java:20)
at io.netty.util.concurrent.DefaultPromise.notifyListener0(DefaultPromise.java:578)
at io.netty.util.concurrent.DefaultPromise.notifyListeners0(DefaultPromise.java:571)
at io.netty.util.concurrent.DefaultPromise.notifyListenersNow(DefaultPromise.java:550)
at io.netty.util.concurrent.DefaultPromise.notifyListeners(DefaultPromise.java:491)
at io.netty.util.concurrent.DefaultPromise.setValue0(DefaultPromise.java:616)
at io.netty.util.concurrent.DefaultPromise.setFailure0(DefaultPromise.java:609)
at io.netty.util.concurrent.DefaultPromise.tryFailure(DefaultPromise.java:117)
at io.netty.channel.nio.AbstractNioChannel$AbstractNioUnsafe.fulfillConnectPromise(AbstractNioChannel.java:321)
at io.netty.channel.nio.AbstractNioChannel$AbstractNioUnsafe.finishConnect(AbstractNioChannel.java:337)
at io.netty.channel.nio.NioEventLoop.processSelectedKey(NioEventLoop.java:707)
at io.netty.channel.nio.NioEventLoop.processSelectedKeysOptimized(NioEventLoop.java:655)
at io.netty.channel.nio.NioEventLoop.processSelectedKeys(NioEventLoop.java:581)
at io.netty.channel.nio.NioEventLoop.run(NioEventLoop.java:493)
at io.netty.util.concurrent.SingleThreadEventExecutor$4.run(SingleThreadEventExecutor.java:989)
at io.netty.util.internal.ThreadExecutorMap$2.run(ThreadExecutorMap.java:74)
at io.netty.util.concurrent.FastThreadLocalRunnable.run(FastThreadLocalRunnable.java:30)
... 1 more
Caused by: io.netty.channel.AbstractChannel$AnnotatedConnectException: Connection refused: no further information: localhost/[0:0:0:0:0:0:0:1]:20347
Caused by: java.net.ConnectException: Connection refused: no further information
at java.base/sun.nio.ch.Net.pollConnect(Native Method)
at java.base/sun.nio.ch.Net.pollConnectNow(Net.java:660)
at java.base/sun.nio.ch.SocketChannelImpl.finishConnect(SocketChannelImpl.java:875)
at io.netty.channel.socket.nio.NioSocketChannel.doFinishConnect(NioSocketChannel.java:330)
at io.netty.channel.nio.AbstractNioChannel$AbstractNioUnsafe.finishConnect(AbstractNioChannel.java:334)
at io.netty.channel.nio.NioEventLoop.processSelectedKey(NioEventLoop.java:707)
at io.netty.channel.nio.NioEventLoop.processSelectedKeysOptimized(NioEventLoop.java:655)
at io.netty.channel.nio.NioEventLoop.processSelectedKeys(NioEventLoop.java:581)
at io.netty.channel.nio.NioEventLoop.run(NioEventLoop.java:493)
at io.netty.util.concurrent.SingleThreadEventExecutor$4.run(SingleThreadEventExecutor.java:989)
at io.netty.util.internal.ThreadExecutorMap$2.run(ThreadExecutorMap.java:74)
at io.netty.util.concurrent.FastThreadLocalRunnable.run(FastThreadLocalRunnable.java:30)
at java.base/java.lang.Thread.run(Thread.java:832)
]]>
    </error>
  </testcase> <!-- verifyUnsuccessfulLoginActionOnLoginPage -->
  <system-out/>
  <testcase classname="local.HLVTestApp.loginandsignuptests.NegativeLoginTests" name="verifyUnsuccessfulLoginActionOnMainPage" time="2.736">
    <failure message="expected [http://localhost:8080/login] but found [http://localhost:8080/?username=testUsername1&amp;password=incorrectPassword]" type="java.lang.AssertionError">
      <![CDATA[java.lang.AssertionError: expected [http://localhost:8080/login] but found [http://localhost:8080/?username=testUsername1&password=incorrectPassword]
at org.testng.Assert.fail(Assert.java:99)
at org.testng.Assert.failNotEquals(Assert.java:1037)
at org.testng.Assert.assertEqualsImpl(Assert.java:140)
at org.testng.Assert.assertEquals(Assert.java:122)
at org.testng.Assert.assertEquals(Assert.java:629)
at org.testng.Assert.assertEquals(Assert.java:639)
at local.HLVTestApp.loginandsignuptests.NegativeLoginTests.verifyUnsuccessfulLoginActionOnMainPage(NegativeLoginTests.java:35)
at java.base/jdk.internal.reflect.NativeMethodAccessorImpl.invoke0(Native Method)
at java.base/jdk.internal.reflect.NativeMethodAccessorImpl.invoke(NativeMethodAccessorImpl.java:64)
at java.base/jdk.internal.reflect.DelegatingMethodAccessorImpl.invoke(DelegatingMethodAccessorImpl.java:43)
at java.base/java.lang.reflect.Method.invoke(Method.java:564)
at org.testng.internal.MethodInvocationHelper.invokeMethod(MethodInvocationHelper.java:133)
at org.testng.internal.TestInvoker.invokeMethod(TestInvoker.java:598)
at org.testng.internal.TestInvoker.invokeTestMethod(TestInvoker.java:173)
at org.testng.internal.MethodRunner.runInSequence(MethodRunner.java:46)
at org.testng.internal.TestInvoker$MethodInvocationAgent.invoke(TestInvoker.java:824)
at org.testng.internal.TestInvoker.invokeTestMethods(TestInvoker.java:146)
at org.testng.internal.TestMethodWorker.invokeTestMethods(TestMethodWorker.java:146)
at org.testng.internal.TestMethodWorker.run(TestMethodWorker.java:128)
at java.base/java.util.ArrayList.forEach(ArrayList.java:1511)
at org.testng.TestRunner.privateRun(TestRunner.java:794)
at org.testng.TestRunner.run(TestRunner.java:596)
at org.testng.SuiteRunner.runTest(SuiteRunner.java:377)
at org.testng.SuiteRunner.access$000(SuiteRunner.java:28)
at org.testng.SuiteRunner$SuiteWorker.run(SuiteRunner.java:418)
at org.testng.internal.thread.ThreadUtil.lambda$execute$0(ThreadUtil.java:64)
at java.base/java.util.concurrent.FutureTask.run(FutureTask.java:264)
at java.base/java.util.concurrent.ThreadPoolExecutor.runWorker(ThreadPoolExecutor.java:1130)
at java.base/java.util.concurrent.ThreadPoolExecutor$Worker.run(ThreadPoolExecutor.java:630)
at java.base/java.lang.Thread.run(Thread.java:832)
]]>
    </failure>
  </testcase> <!-- verifyUnsuccessfulLoginActionOnMainPage -->
  <system-out/>
  <testcase classname="local.HLVTestApp.loginandsignuptests.NegativeLoginTests" name="verifyUnsuccessfulLoginActionOnLoginPage" time="3.147"/>
  <system-out/>
</testsuite> <!-- local.HLVTestApp.loginandsignuptests.NegativeLoginTests -->
